Workbook
Name _sc38: #REF!
Name Excel_BuiltIn__FilterDatabase_4: #REF!
Name __NF4: #REF!
Name mbw: #REF!
Name ____________________b111121: #REF!
Name CABLE_1_6_7: #REF!
Name Staircase: #REF!
Name CABLE_1_12: #REF!
Name __MC4: #REF!
Name ClientPhone: #REF!
Name _MC4: #REF!
Name DFG: #REF!
Name current3: #REF!
Name Overall_Summary_Title: #REF!
Name Field63: #REF!
Name _______________________Ki1: #REF!
Name ProjAddress1: #REF!
Name Excel_BuiltIn_Print_Area_3_1_1: #REF!
Name Engineering_total: #REF!
Name SP1Number: #REF!
Name Excel_BuiltIn_Print_Area_48: #REF!
Name Material: #REF!
Name ContWithAcct: #REF!
Name mmmmmmmmmm: #REF!
Name kb: #REF!
Name _a_1_6_7: #REF!
Name aeron: #REF!
Name ciff: #REF!
Name _900: #REF!
Name Full_Print: #REF!
Name Princ: #REF!
Name u: #REF!
Name A8____0: #REF!
Name Excel_BuiltIn_Print_Area_5_4: #REF!
Name ProdPct1: #REF!
Name _______________________TB2: #REF!
Name si: #REF!
Name I___13: #REF!
Name Q행: #REF!
Name CompRange1Main: #REF!
Name kc: #REF!
Name ______TB2: #REF!
Name _SDB5.: #REF!
Name Excel_BuiltIn_Print_Area_1_1_1_1: #REF!
Name ValveConn: #REF!
Name K_Genehmigung: #REF!
Name UFPrn20070606150313: #REF!
Name Lr: #REF!
Name _30cd__Vertical_strobe_light__wall_mounted: #REF!
Name Field319: #REF!
Name ww: #REF!
Name zlpu___0: #REF!
Name _sc36: #REF!
Name fff: #REF!
Name _Ki2: #REF!
Name Client_Equipment_Total: #REF!
Name Excel_BuiltIn_Print_Area_3_1_1_1: #REF!
Name WES: #REF!
Name Field288: #REF!
Name ___________________TB2: #REF!

Sheet General Notes
A2: PREAMBLE FOR CIVIL & INTERIOR WORKS
B4: GENERAL NOTES COVERING BILL OF QUANTITIES
B6: General Applicability
B7: These notes shall apply to all Bills of Quantities forming part of this document.
B8: The Works under this Bill shall be priced based on re-measurable quantities unless otherwise mentioned.
B9: This Bill shall be read in conjunction with the Drawings, Specifications of Materials and Workmanship, General Conditions of Contract, and all other associated Bills of Quantities. All these documents shall be construed as being complementary to one another, and any requirement shown on one shall be binding as though it appeared on all.
B10: The Contractor shall provide and execute everything reasonably necessary for the proper completion of the Works according to the true intent and meaning of the Drawings, Specifications, and Contract Documents, whether or not the same is specifically mentioned, provided that it can be reasonably inferred therefrom.
B11: In the event of any discrepancy between the Drawings, Specifications, or any other Contract Documents, the same shall be immediately brought to the notice of the Employer’s Representative / Consultant, whose decision shall be final and binding.
B12: Tenderers shall carefully examine all drawings, specifications, site conditions, and existing services before submitting their bid, and shall satisfy themselves as to the nature and scope of the works to be carried out. No claim shall be entertained on account of lack of knowledge of site conditions.
B13: Unit rates shall be inclusive of all mock-ups, samples, protection, cleaning, rectification, and housekeeping till handover.
B14: Quoted rate shall include all charges towards transportation, lead, lift, mathadi charges , Octroi, installation, levies, royalties, WCP & CAR insurance & other applicable insurances, ESI & PF premiums, overheards, fees and rectification of defects or replacement of defective material.
B16: Scope of Work and Pricing Requirements
B17: The rates and prices quoted shall be deemed to include the entire scope of work as defined in the Drawings, Specifications, and BOQ.
... B146: MS – Mild Steel

Sheet FINAL SUMMARY
A1: Project: KOHLER_PUNE
A2: Commercial Proposal by: FLIPSPACES TECHNOLOGY LABS PRIVATE LIMITED
A4: BILL OF QUANTITIES
B5: PROJECT AREA (SFT) - Approx | C5: 14905
A6: S.No. | B6: Cost Heads | C6: AMOUNT (INR) | D6: Rate Per Sft
A8: A | B8: ARCHITECTURAL WORKS : CIVIL AND INTERIORS | C8: =SUM(C9:C17) -> 31707619 | D8: =SUM(D9:D17) -> 2127.3143
A9: A1 | B9: CIVIL WORKS | C9: ='Civil Works'!H51 -> 3917558.5 | D9: =C9/$C$5 -> 262.83519
A10: A2 | B10: INTERIOR WORKS | C10: ='Interior Works'!I274 -> 20810221 | D10: =C10/$C$5 -> 1396.1906
A11: A3 | B11: MODULAR GLASS PARTITIONS AND DOORS | C11: ='Modular Glass Partition & Doors'!H37 -> 2074408 | D11: =C11/$C$5 -> 139.17531
A12: A4 | B12: SIGNAGES | C12: =Signages!H24 -> 433192 | D12: =C12/$C$5 -> 29.063536
A13: A5 | B13: GRAPHICS AND FILMS | C13: ='Graphics and Films'!H19 -> 313695 | D13: =C13/$C$5 -> 21.046293
A14: A6 | B14: BLINDS | C14: =Blinds!H10 -> 906562.95 | D14: =C14/$C$5 -> 60.822741
A15: A7 | B15: PLANTERS | C15: =Planters!G19 -> 426099 | D15: =C15/$C$5 -> 28.587655
A16: A8 | B16: TOILET WORKS | C16: ='TOILET WORKS'!H188 -> 2825883 | D16: =C16/$C$5 -> 189.59296
A18: B | B18: FURNITURE AND FURNISHING | C18: =SUM(C19:C22) -> 4937260.8 | D18: =SUM(D19:D22) -> 331.24863
A19: B1 | B19: CARPET FLOORING | C19: ='Carpet Flooring'!H8 -> 1326820.8 | D19: =C19/$C$5 -> 89.018502
A20: B2 | B20: MODULAR FURNITURE | C20: ='Modular Furniture'!H43 -> 1394656 | D20: =C20/$C$5 -> 93.569675
A21: B3 | B21: LOOSE FURNITURE & CHAIRS | C21: ='Loose Furniture & Chairs'!H36 -> 2215784 | D21: =C21/$C$5 -> 148.66045
A23: C | B23: ELECTRICAL WORKS | C23: =SUM(C24:C26) -> 8768969 | D23: =SUM(D24:D26) -> 588.32399
A24: C1 | B24: ELECTRICAL WORKS | C24: ='Electrical Works'!I710 -> 6382430 | D24: =C24/$C$5 -> 428.20731
A25: C2 | B25: LIGHT FIXTURES | C25: ='Light Fixtures'!I29 -> 2386539 | D25: =C25/$C$5 -> 160.11667
A27: D | B27: HVAC | C27: =SUM(C28:C29) -> 7528130.5 | D27: =SUM(D28:D29) -> 505.07417
A28: D1 | B28: HVAC | C28: =HVAC!H265+HVAC!F265 -> 7528130.5 | D28: =C28/$C$5 -> 505.07417
A30: E | B30: DATA NETWORK | C30: =C31 -> 1931970 | D30: =D31 -> 129.61892
A31: E1 | B31: PASSIVE NETWORKING | C31: ='Passive Networking'!G54 -> 1931970 | D31: =C31/$C$5 -> 129.61892
A33: F | B33: PHE WORKS | C33: =SUM(C34) -> 160300 | D33: =SUM(D34) -> 10.75478
A34: F1 | B34: PLUMBING WORKS | C34: =PHE!J100 -> 160300 | D34: =C34/$C$5 -> 10.75478
A36: G | B36: FLSS WORKS | C36: 400000 | D36: =C36/C5 -> 26.836632 | E36: refurbishment of existing fire services with minimum modification.
A37: G1 | B37: FIRE SPRINKLERS | D37: =C37/$C$5 -> 0
A38: G2 | B38: FIRE DETECTION SYSTEM | D38: =C38/$C$5 -> 0
A39: G3 | B39: PUBLIC ADDRESS SYSTEM | D39: =C39/$C$5 -> 0
A40: G4 | B40: FIRE EXTINGUISHERS | D40: =C40/$C$5 -> 0
A42: H | B42: OTHER ITEMS | C42: =SUM(C43,C44) -> 1569750 | D42: =SUM(D43,D44) -> 105.31701
A43: H1 | B43: DISHWASH AREA | C43: ='Dishwash Area'!H42 -> 666540 | D43: =C43/$C$5 -> 44.719222
A44: H2 | B44: KITCHEN EQUIPMENTS & OTHERS | C44: ='Kitchen Equipments'!I21 -> 903210 | D44: =C44/$C$5 -> 60.597786
A46: I | B46: AV WORKS | D46: =SUM(D47) -> 0 | E46: Excluded from scope
A47: I1 | B47: AV WORKS | D47: =C47/$C$5 -> 0 | E47: Excluded from scope
B49: TOTAL (EXCLUSIVE OF TAXES) | C49: =sum(C33,C36,C30,C27,C23,C18,C8,C42) -> 57004000 | D49: =sum(D33,D36,D30,D27,D23,D18,D8,D42) -> 3824.4884
B51: GRAND TOTAL (EXCLUSIVE OF TAXES) | C51: =C49 -> 57004000 | D51: =C51/C5 -> 3824.4884
B52: GST @ 18% | C52: =C51*18% -> 10260720
...

Sheet Copy of FINAL SUMMARY
A1: Project: KOHLER_PUNE
A2: Commercial Proposal by: FLIPSPACES TECHNOLOGY LABS PRIVATE LIMITED
A4: BILL OF QUANTITIES
B5: PROJECT AREA (SFT) - Approx | C5: 14905
A6: S.No. | B6: Cost Heads | C6: AMOUNT (INR) | D6: Rate Per Sft
A8: A | B8: ARCHITECTURAL WORKS : CIVIL AND INTERIORS | C8: 31707620 | D8: =SUM(D9:D17) -> 2127.3143
A9: A1 | B9: CIVIL WORKS | C9: 3917559 | D9: =C9/$C$5 -> 262.83522
A10: A2 | B10: INTERIOR WORKS | C10: 20810221 | D10: =C10/$C$5 -> 1396.1906
A11: A3 | B11: MODULAR GLASS PARTITIONS AND DOORS | C11: 2074408 | D11: =C11/$C$5 -> 139.17531
A12: A4 | B12: SIGNAGES | C12: 433192 | D12: =C12/$C$5 -> 29.063536
A13: A5 | B13: GRAPHICS AND FILMS | C13: 313695 | D13: =C13/$C$5 -> 21.046293
A14: A6 | B14: BLINDS | C14: 906563 | D14: =C14/$C$5 -> 60.822744
A15: A7 | B15: PLANTERS | C15: 426099 | D15: =C15/$C$5 -> 28.587655
A16: A8 | B16: TOILET WORKS | C16: 2825883 | D16: =C16/$C$5 -> 189.59296
A18: B | B18: FURNITURE AND FURNISHING | C18: 4937261 | D18: =SUM(D19:D22) -> 331.24864
A19: B1 | B19: CARPET FLOORING | C19: 1326821 | D19: =C19/$C$5 -> 89.018517
A20: B2 | B20: MODULAR FURNITURE | C20: 1394656 | D20: =C20/$C$5 -> 93.569675
A21: B3 | B21: LOOSE FURNITURE & CHAIRS | C21: 2215784 | D21: =C21/$C$5 -> 148.66045
A23: C | B23: ELECTRICAL WORKS | C23: 8768969 | D23: =SUM(D24:D26) -> 588.32399
A24: C1 | B24: ELECTRICAL WORKS | C24: 6382430 | D24: =C24/$C$5 -> 428.20731
A25: C2 | B25: LIGHT FIXTURES | C25: 2386539 | D25: =C25/$C$5 -> 160.11667
A27: D | B27: HVAC | C27: =C28 -> 7528130 | D27: =SUM(D28:D29) -> 505.07414
A28: D1 | B28: HVAC | C28: 7528130 | D28: =C28/$C$5 -> 505.07414
A30: E | B30: DATA NETWORK | C30: 1931970 | D30: =D31 -> 129.61892
A31: E1 | B31: PASSIVE NETWORKING | C31: 1931970 | D31: =C31/$C$5 -> 129.61892
A33: F | B33: PHE WORKS | C33: =C34 -> 160300 | D33: =SUM(D34) -> 10.75478
A34: F1 | B34: PLUMBING WORKS | C34: 160300 | D34: =C34/$C$5 -> 10.75478
A36: G | B36: FLSS WORKS | C36: 400000 | D36: =C36/C5 -> 26.836632
A37: G1 | B37: FLSS WORKS (Refurbishment of existing services) | C37: =C36 -> 400000 | D37: =C37/C$5 -> 26.836632
A39: H | B39: OTHER ITEMS - DISHWASH & KITCHEN AREA | C39: =sum(C40:C41) -> 1569750 | D39: =sum(D40:D41) -> 105.31701
A40: H1 | B40: DISHWASH AREA | C40: 666540 | D40: =C40/C$5 -> 44.719222
A41: H2 | B41: KITCHEN EQUIPMENTS & OTHERS | C41: 903210 | D41: =C41/C$5 -> 60.597786
B43: TOTAL (EXCLUSIVE OF TAXES) | C43: =sum(C33,C36,C30,C27,C23,C18,C8,C39) -> 57004000 | D43: =sum(D33,D36,D30,D27,D23,D18,D8,D39) -> 3824.4884
B44: GST @ 18% | C44: =C43*0.18 -> 10260720
B45: GRAND TOTAL (WITH TAXES) | C45: 67264720

Sheet EXT FINAL SUMMARY
A1: Project: KOHLER_PUNE
A2: Commercial Proposal by: FLIPSPACES TECHNOLOGY LABS PRIVATE LIMITED
A4: BILL OF QUANTITIES
B5: PROJECT AREA (SFT) - Approx | C5: 14905
A6: S.No. | B6: Cost Heads | C6: AMOUNT (INR) | D6: Rate Per Sft
A8: A | B8: ARCHITECTURAL WORKS : CIVIL AND INTERIORS | C8: 31707620 | D8: =SUM(D9:D17) -> 2127.3143
A9: A1 | B9: CIVIL WORKS | C9: 3917559 | D9: =C9/$C$5 -> 262.83522
A10: A2 | B10: INTERIOR WORKS | C10: 20810221 | D10: =C10/$C$5 -> 1396.1906
A11: A3 | B11: MODULAR GLASS PARTITIONS AND DOORS | C11: 2074408 | D11: =C11/$C$5 -> 139.17531
A12: A4 | B12: SIGNAGES | C12: 433192 | D12: =C12/$C$5 -> 29.063536
A13: A5 | B13: GRAPHICS AND FILMS | C13: 313695 | D13: =C13/$C$5 -> 21.046293
A14: A6 | B14: BLINDS | C14: 906563 | D14: =C14/$C$5 -> 60.822744
A15: A7 | B15: PLANTERS | C15: 426099 | D15: =C15/$C$5 -> 28.587655
A16: A8 | B16: TOILET WORKS | C16: 2825883 | D16: =C16/$C$5 -> 189.59296
A18: B | B18: FURNITURE AND FURNISHING | C18: 4937261 | D18: =SUM(D19:D22) -> 331.24864
A19: B1 | B19: CARPET FLOORING | C19: 1326821 | D19: =C19/$C$5 -> 89.018517
A20: B2 | B20: MODULAR FURNITURE | C20: 1394656 | D20: =C20/$C$5 -> 93.569675
A21: B3 | B21: LOOSE FURNITURE & CHAIRS | C21: 2215784 | D21: =C21/$C$5 -> 148.66045
A23: C | B23: ELECTRICAL WORKS | C23: 8768969 | D23: =SUM(D24:D26) -> 588.32399
A24: C1 | B24: ELECTRICAL WORKS | C24: 6382430 | D24: =C24/$C$5 -> 428.20731
A25: C2 | B25: LIGHT FIXTURES | C25: 2386539 | D25: =C25/$C$5 -> 160.11667
A27: D | B27: HVAC | C27: =C28 -> 7528130 | D27: =SUM(D28:D29) -> 505.07414
A28: D1 | B28: HVAC | C28: 7528130 | D28: =C28/$C$5 -> 505.07414
A30: E | B30: DATA NETWORK | C30: 1931970 | D30: =D31 -> 129.61892
A31: E1 | B31: PASSIVE NETWORKING | C31: 1931970 | D31: =C31/$C$5 -> 129.61892
A33: F | B33: PHE WORKS | C33: =C34 -> 160300 | D33: =SUM(D34) -> 10.75478
A34: F1 | B34: PLUMBING WORKS | C34: 160300 | D34: =C34/$C$5 -> 10.75478
A36: G | B36: FLSS WORKS | C36: 400000 | D36: =C36/C5 -> 26.836632
A37: G1 | B37: FLSS WORKS (Refurbishment of existing services) | C37: =C36 -> 400000 | D37: =C37/C$5 -> 26.836632
A39: H | B39: OTHER ITEMS - DISHWASH & KITCHEN AREA | C39: =sum(C40:C41) -> 1569750 | D39: =sum(D40:D41) -> 105.31701
A40: H1 | B40: DISHWASH AREA | C40: 666540 | D40: =C40/C$5 -> 44.719222
A41: H2 | B41: KITCHEN EQUIPMENTS & OTHERS | C41: 903210 | D41: =C41/C$5 -> 60.597786
B43: TOTAL (EXCLUSIVE OF TAXES) | C43: =sum(C33,C36,C30,C27,C23,C18,C8,C39) -> 57004000 | D43: =sum(D33,D36,D30,D27,D23,D18,D8,D39) -> 3824.4884
B44: GST @ 18% | C44: =C43*0.18 -> 10260720
B45: GRAND TOTAL (WITH TAXES) | C45: =C44+C43 -> 67264720

Sheet Exclusion
A2: LIST OF EXCLUSIONS
A3: ACTIVE NETWORKING
A4: COMPACTOR / SLOTTED ANGLE RACKS
A5: VIDEO CONFERENCING EQUIPMENT
A6: EPABX
A7: TELEPHONE INSTRUMENTS
A8: LED SCREENS
A9: POLYCOM INSTRUMENTS
A10: PHOTOCOPIER
A11: UPS BATTERIES AND HARDWARE
A12: COMPUTERS/LAPTOPS ETC
A13: PRINTERS
... A47: AV WORKS

Sheet Payment Terms
B3: RA | C3: Day | D3: Payment | E3: Milestone
B4: Advance Payment | C4: 0 | D4: 0.3 | E4: Project mobilisation.
B5: RA1 | C5: 45 | D5: 0.2 | E5: Execution: Demolition, partition line marking, frameworks, single-side skinning, civil wall, plastering, plumbing, ceiling and wall electrical conduiting, floor raceway laying. Material delivery: gypsum frames, gypsum sheets, electrical conduits and raceway, siporex blocks. Key order closures: HVAC, fire alarm system, carpentry.
B6: RA2 | C6: 70 | D6: 0.15 | E6: Execution: closing of partitions from double side, electrical wiring, fire sprinkler piping, FAS wiring. Material delivery: duct material, wires/cables, ply for carpentry items, vitrified tiles. Key order closures: modular furniture, chairs, carpets, glass.
B7: RA3 | C7: 85 | D7: 0.15 | E7: Execution: painting base-coat preparation, glass channel, HVAC duct installation, false ceiling framing. Material delivery: carpets, sanitary fittings and fixtures, doors, DB/MCB. Key order closures: decorative elements, glass films, wallpapers, canvas frames, branding.
B8: RA4 | C8: 110 | D8: 0.15 | E8: Execution: electrical switches/sockets, sanitary fixtures, carpentry structures ready, flush doors, first coat of paint, false ceiling, before HVAC final commissioning and before LV commissioning. Material delivery: modular furniture on site, carpet on site and before chair delivery. Key order closure: deep cleaning.
B9: RA5 | C9: 120 | D9: 0.05 | E9: Release against unconditional bank guarantee of equal amount, valid for 6 months Defects Liability Period.
D11: =sum(D4:D9) -> 1
B12: * Payment to be released within 15 days from invoice date

Sheet Civil Works
A1: SL NO | B1: ITEM DESCRIPTION | C1: LOCATION | D1: BASIC RATE | E1: UNIT | F1: QTY | G1: RATE(INR) | H1: AMOUNT(INR) | I1: REMARKS
A3: 1 | B3: CIVIL WORKS
A5: 1.1 | B5: AAC (AUTOCLAVED AERATED CONCRETE) Block Wall
B6: Providing and constructing autoclaved 6" thick wall of 150mm X 240mm X 600mm Light Weight Block in proper line and level, at all levels in cement mortor 1:4 (1 cement and 4 river sand) using standard size of blocks. Rate shall include providing concrete binders in proportion 1:2:4, RCC binder to be at every 1mtr interval from floor level. The rate to be inclusive of cost of reinforcement and formwork, cover block for reinforcement and all other incidental charges etc., all complete and as directed. The rate shall also include closing the gap between the masonary and RCC beam/ slab finished to required slope.
A7: a | B7: 150mm Thik AAC Block Wall | C7: CRITICAL ZONE, PANTRY | E7: SQM | F7: 120 | G7: 1692 | H7: =G7*F7 -> 203040
A9: 1.2 | B9: Gypsum Plaster
B10: Providing and applying 10 mm thick (average) premixed gypsum plaster of approved make (e.g., Saint Gobain Gyproc) with special additives, conforming to IS:2547 Part I & II–1976, applied in one or two coats over internal surfaces such as gypsum boards, wooden partitions, and false ceiling areas. The surface shall be prepared by cleaning, treating wooden substrates with suitable bonding agents, and applying approved bonding chemical (e.g., Gyproc Bondit) on RCC areas wherever applicable. Chicken mesh to be fixed at all junctions—between blockwork, RCC elements, patli bands, mullions, and wooden framing—to prevent cracks. The plaster shall be finished smooth, in line, level, and plumb, free of undulations, ready for paint finish. Rates include all labour, materials, adhesives, scaffolding, and execution as per architect’s directions.
A11: a | B11: Block Work with Paint | C11: New construction | E11: SQM | F11: 300 | G11: 464 | H11: =G11*F11 -> 139200
A12: b | B12: Builder Walls | C12: AHU, Existing walls | E12: SQM | F12: 150 | G12: 464 | H12: =G12*F12 -> 69600
A14: 1.3 | B14: Cement Plastering | E14: SQM | F14: 110 | G14: 484 | H14: =G14*F14 -> 53240
B15: Providing and applying 12 mm to 15 mm thick cement plaster in 1:5 mix (1 part cement : 5 parts sand — 75% fine and 25% coarse sand) using approved readymade dry mix on blockwork, brickwork, and RCC surfaces. Includes surface preparation, cleaning, wetting, and hacking wherever required. Plaster to be applied evenly in true line, level, and plumb, finished with a smooth trowel finish. Necessary curing to be carried out to ensure strength and durability, all as per architect’s instructions and approved specifications.
A17: 1.4 | B17: Self levelling (3-5mm thickness) | C17: Areas with Carpet/LVT | E17: SQM | F17: 605 | G17: 338 | H17: =G17*F17 -> 204490
B18: Providing and laying of Ardex Commercial levelling cementitious flooring system Surface preparation: Removing all existing weak, un sound CC floor to reach the strong substrate, cleaning the floor area to make it free from all contaminants and complete as per manufacturer's specification. Providing and applying Ardex P 51 primer to the base substrate and allow it to dry completely. Providing and mixing of CL 11, commercial levelling compound consisting of high quality special cement and selected fillers, with water at rate of 5.5-6 Ltr for 25 Kg bag of CL 11, installing at required 3mm to 5mm thickness using suitable pin rake trowel and notch trowel, finally rolling the surface with spike roller and allowed to dry completely, installing vinyl /LVT flooring as per client's requirement, etc and complete as per manufacturer's specification. [ The properties shall confirm to:- Bulk density of powder: Approx. 1.3 kg / Ltr; Weight of fresh mortar: Approx. 2.0 kg / Ltr; Working time: Approx. 25 min; Flow life: Approx. 15 min; Initial set (Vicat): Approx. 40 min; Final set (Vicat) Approx. 1 hr; Ball impact hardness: 6.5mm; Scratch hardness: 1.6mm; Compressive strength: 20 N / mm2
A20: =A17+0.1 -> 1.5 | B20: PCC - upto 75-100mm thick for complete floor area | C20: ENTIRE AREA | E20: SQM | F20: 1400 | G20: 1015 | H20: =G20*F20 -> 1421000
B21: Providing & laying plain cement concrete 1:3:6 nominal mix (1 cement :3 coarse sand : 6 graded stone aggregate 25 mm nominal size) of approved quality with all lead & lift below/above the ground level as per drawing including the cost of cement, levelling of surface of concrete with al lead and lift, labour, material as per specifications and directed by Architect up to thickness of 75-100mm.
A23: =A20+0.1 -> 1.6 | B23: POP Punning
B24: Providing and applying of Plaster of Paris Punning (1st Quality ISI approved POP) over plastered with minimum thickness of 8mm-12mm to existing wall surfaces , column & concrete members etc., to be finished in line and plumb with smooth surface ready to receive paint base. Rate to be inclusive of hacking wall surfaces for better bonding, cleaning, scrubbing the surface, providing grooves if necessary etc., complete as per architect's approval. | C24: Existing Walls | E24: SQM | F24: 120 | G24: 300 | H24: =G24*F24 -> 36000
A26: =A23+0.1 -> 1.7 | B26: RCC Lintel (for Doors) | C26: HUB ROOM | E26: RMT | F26: 6.5 | G26: 2127 | H26: =G26*F26 -> 13825.5
B27: Providing and laying in place reinforced cement concrete with cement concrete of grade 1:2:4 (1 cement: 2 fine aggregates: coarse aggregates) in Lintels, beam counters, shelves etc., at all heights & width and level, including vibrating and curing. Rate shall include cost of centring and shuttering including strutting, propping etc. and removal of form for all heights. The rate shall also include for reinforcement with Fe500 grade TMT bars including straightening, cutting, bending, placing in position and binding all complete.
A29: =A26+0.1 -> 1.8 | B29: Cinder filling - Including cinder filling / block work required to raise the floor area, Pantry / Kitchen | C29: PANTRY | E29: CUM | F29: 25 | G29: 12088 | H29: =G29*F29 -> 302200
B30: Providing and filling Cinder to an average depth of up to 300 mm at locations as indicated on the drawings or as instructed by the architects. Cost to include for proper compaction of the laid cinder and filling the complete area with 1:3:6 cement concrete to fill all gaps in the cinder to form a level even surface on top. The rate shall be inclusive of creating ramp from floor finish to raised area.
A32: =A29+0.1 -> 1.9 | B32: Raised Flooring - 150mm Height | C32: DISHWASH AREA, HANDWASH AREA | E32: SQM | F32: 30 | G32: 1354 | H32: =G32*F32 -> 40620
B33: Providing and laying in line and level up to 150mm height on sunken areas broken light weight concrete block bats of approximately 600 kg. per cum density laid, consolidated, finished smooth, the rate shall be inclusive of 50 mm thk pcc flooring with cement concrete 1:2:4 (1 unit - cement, 2 units - sand, 4 units - coarse aggregates) to receive final smooth finish.
A35: 1.1 | B35: Waterproofing (For Floor + Walls 600 mm High) | C35: DISHWASH AREA, HANDWASH AREA | E35: SQM | F35: 50 | G35: 1015 | H35: =G35*F35 -> 50750
B36: Providing of water proofing - chemical Treatment – the slab to be cleaned and apply 3 coats of chemical on the floor. Base coat – Applying base coat of 1:6 mortar over chemical treatment on the floor and on the peripheral walls upto 600mm.Cost of the water proofing shall include cleaning of the surface of all dirt and grit before the application. The water proofed area shall be ponded and tested for a minimum of 24 hours or as per manufacturer's specification. Note - Warranty to be provided upto 10 years
B37: * Clean surface to remove all dust, foreign matters, loose particles or any deposits of contaminants which could affect the bond between the surface and waterproof coating. * Remove all sharp projections and make surface reasonably smooth * Thoroughly pre-wet all concrete surfaces for at least one hour prior to application of coating, by ponding of water on flat surfaces and by vigorous spraying of water on vertical surfaces. * Remove all water from surfaces prior to applying of water proof coating, so that the surface is only damp or surface dry. Standing water or shiny wet surface shall not be present under any circumstances * Apply water proof coating / Brush Topping as specified for various conditions. * Apply 12mm thick cement plaster 1:4 (1cement : 4 coarse sand) after applications of final coat. * After application of final coat of Tape Crete, allow to air dry for 4-6 hours. Do not use any water for curing during this time. * In case of high temperatures and low humidity combined with high wind condition, cover the coating with polythene sheet to prevent rapid drying. * Maximum 6 hours after final application, moist cure for 24 hours by spraying water. Ensure that at no time during this 24 hour period the coating is completely dry or completely submerged in water. * After moist curing, allow to air dry for 3 days. * After air drying, complete the curing by submersion in water for 24 hours.
A39: 1.11 | B39: Pest Control and Anti-Termite Treatment | C39: Entire Floor | E39: SQM | F39: 1400 | G39: 73 | H39: =G39*F39 -> 102200
B40: Providing & applying Pest Control & Anti-termite treatment by appointing a specialized agency. All work shall in general be executed as specified in IS : 6313 Part II-1981 & as per approved specification of the agency having special know-how for the job. All necessary work to ensure uniform distribution & proper penetration of treatment of treating solution shall be done according to the instruction of the Engineer. This includes treatment to floor area, Walls, Soil Surrounding pipes, Waste & Conduits, Expansion Joints, Junction of the Wall & the floor, Timber & Carpentry Works, Gypsum related works, etc all complete as per the instructions of architect. Pest control need to be done in 3 steps including periodic monthly fumigation and pest control at stores/site/temporary off as EHS requirement. Note: 10 year warranty to be provided on stamp paper.
A42: =A39+0.01 -> 1.12 | B42: Floor chipping upto 100mm thk | C42: - | E42: SQM | F42: 200 | G42: 290 | H42: =G42*F42 -> 58000
B43: Cutting of screed and then chipping of existing hard screed floor and carry debris away from site as per PM instructions. Cost to include levelling the chipped floor area wherever required. Necessary protection with polythene sheet to be provided while execution of floor chipping.
A45: =A42+0.01 -> 1.13 | B45: Dismantling of Doors , Partitions, False flooring etc + Salvage | E45: LS | F45: 1 | G45: 483593 | H45: =G45*F45 -> 483593
B46: Dismantling and removal of existing partitions( gypsum or glass ), ceiling, flooring, wall finishes, furniture, and MEP items. Including protection of base structure, debris disposal, and handing over the site in clean bare shell condition ready for fit-out. Salvaging the material dismantled and not utilized is in contractor's scope
A48: =A45+0.01 -> 1.14 | B48: Debris Removal | E48: Loads | F48: 90 | G48: 8220 | H48: =G48*F48 -> 739800
B49: "Collection, loading, transportation, and disposal of construction debris, excavated soil, and dismantled material from site to an approved dumping location (as per State PCB Norms). Includes all labour, tools, transportation, Mathadi, and incidental charges, ensuring site is left clean and level as directed by the Project Manager. 1 Load = 1 Truck/ Large Vehicle"
B51: TOTAL FOR CIVIL WORKS | H51: =sum(H5:H50) -> 3917558.5

Sheet Interior Works
A1: SL NO | B1: ITEM DESCRIPTION | C1: LOCATION | D1: REFERENCE IMAGE | E1: BASIC RATE | F1: UNIT | G1: QTY | H1: RATE(INR) | I1: AMOUNT(INR) | J1: REMARKS
A3: 1 | B3: FLOORING WORKS
A5: 1.1 | B5: Vitrified Tile Flooring (Level to Match Finished Floor Level)
B6: Providing & laying vitrified flooring with 1st quality homogeneous tiles of approved make, of size as per details, set in average 10mm thk approved tile based adhesive or 1:4 CM upto 30mm average thickness as per site conditions. Rate to include for laying tiles to the pattern as directed by Architect/Consultant including curing, soft cleaning chemical wash etc. Tiles to be laid with spacers (4mm) in-between as per architects/PM instructions. Rate to include the cutting the tiles to size if there are any variations. Cost should include house keeping & cleaning for the vitrified flooring till the handover. Tile to tile joints to be filled with epoxy grout of approved shade. Quoted rate to include the cost of curing, protection with polythene sheet and POP overlay till hand-over.
A7: a | B7: Tile - Type -01 (Size: 600mm X 600mm) | C7: HAND WASH AREA, DISHWASH AREA, TUCK SHOP | E7: INR 80/SFT | F7: SQM | G7: 85 | H7: 2021 | I7: =H7*G7 -> 171785 | J7: Basic Rate: Vitrified Tile - INR 60/SFT
A8: b | B8: Designer Tile - 02 (Size: 300mm X 600mm ) | C8: CAFETERIA | E8: INR 150/SFT | F8: SQM | G8: 50 | H8: 2756 | I8: =H8*G8 -> 137800 | J8: Basic Rate: Pattern Tile - INR 80/SFT
A10: 1.2 | B10: Subway Tile Dado / Cladding
B11: Providing & cladding of Premium vitrified tiles or stone-finish ceramic tiles with specified slip resistance. tile dadoing with 1st quality homogeneous tiles of approved make, of size as per drawings, set in average 6mm thk approved tile based adhesive or CM 1:4. Rate to include for cladding tiles to the pattern as directed by Architect / Consultant, including curing, approved chemical wash etc. Tiles to be cladded with 3mm spacers in between as per architects/PM instructions. Rate to include the cutting the tiles to size if there are any variations. Cost should include house keeping & cleaning of vitrified dadoing till the handover. Rate to include approved epoxy grouting matching to tile colour and also to include cladding of tile with necessary adhesive as per Architects /Pms instructions. Rate to include necessary corner beading / Fine edge curve 10mm corner guard profile to match the tile shade. To have necessary provision for switch cutout other necessary services cut out to be considered. Make: Kajaria, Nitco, Somany.
A12: a | B12: Tile Cladding (300mm X 100mm) - Type 1 | C12: TUCK SHOP, DRY PANTRY | E12: INR 150/SFT | F12: SQM | G12: 12 | H12: 2848 | I12: =H12*G12 -> 34176 | J12: Basic Rate: Wall Tile INR 80/SFT
A13: b | B13: Tile Cladding (600mm X 600mm) - Type 2 | C13: DISHWASH, HAND WASH | E13: INR 100/SFT | F13: SQM | G13: 90 | H13: 2021 | I13: =H13*G13 -> 181890 | J13: Basic Rate: Wall Tile INR 80/SFT
A15: 1.3 | B15: Epoxy Flooring ( Normal)
B16: Providing and applying 2–3 mm thick self-leveling, anti-static, chemical-resistant epoxy flooring in AHU, electrical, UPS, hub, battery, and server rooms using a multi-layer epoxy system of approved make. Surface preparation shall include cleaning, grinding, and priming to ensure proper adhesion. Application shall consist of base coat, conductive copper strip/grid (where required), intermediate coat, and a final topcoat in approved shade with semi-gloss/smooth finish. The flooring shall be non-dusting, jointless, easy to maintain, and resistant to moisture, oils, and chemicals. Includes coving at wall junctions up to 100 mm height, finishing around cut-outs, and all necessary edge detailing. Execution to be carried out in accordance with manufacturer specifications and under the supervision of architect. | C16: HUB ROOM | F16: SQM | G16: 10 | H16: 1378 | I16: =H16*G16 -> 13780
A18: 1.4 | B18: Antistatic Raised Flooring - 300mm Height | C18: HUB ROOM | F18: SQM | G18: 10 | H18: 5053 | I18: =H18*G18 -> 50530
B19: Providing & Fixing antistatic laminate False flooring / Raised floor as per approved sample and as per manufacturer's specifications with 1.5mm thk antistatic laminate, with 600mm x 600mm grid made of fully removable flooring panels with all uncut panels to be interchangeable. The access floor panel type shall be Solid fill of unitized welded steel construction, cementations filled. Panel shall be factory finished with soft surface laminate. The panel edge trim shall have PVC. Floor panel support structure shall be treated to prevent corrosion. Pedestals shall be of adjustable height and will accommodate stringers of approved make or as per the Technical Specification document of the Architect. The vertical surface to be close similar to the horizontal surface. Quoted Rate shall include all materials, labour, tools & tackles, lead & lift, surface preparation, cleaning and etc.., complete at all levels as per the drawings, specifications and as directed by the Engineer In charge.
A21: =A18+0.1 -> 1.5 | B21: Marble flooring
B22: laying Italian marble flooring using selected grade marble slabs of approved make, color, and thickness (typically 18–20 mm), machine-cut and mirror-polished, laid over a cement mortar bed (1:4) or tile adhesive as per site requirement. The surface shall be prepared, leveled, and cured before laying. Marble pieces shall be laid in desired pattern with matching veins and grain flow, maintaining tight joints and proper alignment. Joints shall be filled with color-matched epoxy grout. The laid surface shall be machine-ground, honed, and polished to achieve a seamless, high-gloss finish. Rates to include edge chamfering, corner detailing, protection, curing, and execution in accordance with architect instructions and approved mock-up. | C22: BOARD ROOM, MD CABIN, RECEPTION, PRODUCTION DISPLAY AREA & PASSAGE | E22: INR 650/SFT | F22: SQM | G22: 290 | H22: 11894 | I22: =H22*G22 -> 3449260 | J22: Basic Rate: INR 500/SFT
A24: =A21+0.1 -> 1.6 | B24: Toughened Glass Flooring
B25: Providing and creating a 225 mm (9") deep sunken floor feature at the reception area, including necessary substructure, waterproofing, MS support framework, clear toughened laminated glass panels with anti-skid finish, integrated planter bed below, concealed warm-white LED strip lighting with aluminium profiles and diffusers, access provisions for maintenance, edge trims, all necessary supports, fixings, wiring, and making good, complete as per approved design and drawings. | C25: RECEPTION | E25: INR 3350/SFT | F25: SQM | G25: 8 | H25: 36746 | I25: =H25*G25 -> 293968 | J25: Basic Rate: INR 1050/SFT
A27: =A24+0.1 -> 1.7 | B27: Water Body Flooring - Product Display Feature
B28: Providing, fabricating and installing a multi-level water body product display feature comprising three stepped tiers of varying heights (1st layer height - 250mm, 2nd layer height- 150mm, 3rd layer height- 300mm to 450mm), including RCC/brick masonry base structure, waterproofing treatment, IPS screed, stone/marble cladding finish, pebble bed infill at each level, concealed recirculating water fountain system with collection sump, SS water nozzles, submersible pumps, filtration system, piping network, control valves, access chambers, concealed LED strip lighting with drivers, electrical wiring, drainage provisions, necessary supports, edge trims, testing & commissioning and all associated civil, electrical and finishing works, complete as per approved design, specifications and drawings. Water shall be recirculated through an integrated filtration and pumping mechanism. | C28: DISPLAY AREA, FEATURE WALL | E28: INR 7500/SFT | F28: SQM | G28: 6 | H28: 83404 | I28: =H28*G28 -> 500424 | J28: Basic Rate: INR 3000/SFT
A30: 1.8 | B30: Wooden Tile Flooring
B31: Providing and fixing 10 mm thick laminated wooden flooring over existing prepared surface, including 4 mm thick foam underlay sheet with polyethylene moisture barrier, click-lock interlocking system, matching skirting/trims, edge profiles, cutting, finishing, and all necessary accessories, complete as per manufacturer's specifications and approved design. | C31: CAFETERIA | E31: INR 150/SFT | F31: SQM | G31: 350 | H31: 1768 | I31: =H31*G31 -> 618800 | J31: Basic Rate: Wooden Tile - INR 120/SFT
A33: 1.9 | B33: Epoxy Water Flooring Under Designer Feature Wall (230 mm Height)
B34: Providing and creating a decorative epoxy water-effect feature trench below the designer feature wall, comprising a 230 mm high recessed base structure, necessary waterproofing treatment, decorative natural river pebbles, self-levelling UV-stable transparent epoxy resin finish to achieve a water-like appearance, edge trims, substrate preparation, necessary supports, formwork, finishing, polishing and all associated materials, labour, accessories and making good works, complete as per approved design and drawings. | C34: FOYER AREA | E34: INR 800/SFT | F34: SQM | G34: 3 | H34: 9187 | I34: =H34*G34 -> 27561 | J34: Basic Rate: INR 200/SFT
B36: TOTAL FOR FLOORING WORKS | I36: =SUM(I3:I35) -> 5479974
A38: 2 | B38: PARTITION & ASSOCIATED WORKS
A40: 2.1 | B40: 100mm Gypsum Board Full Height Partition Without Finish - GI Framework (Both Side GYP Board) | C40: ALL AREAS | F40: SQM | G40: 295 | H40: 3170 | I40: =H40*G40 -> 935150
B41: Providing and fixing full height 100mm thick partition with GI framework of approved brand @ 600 mm c/c both ways finished with Double layer of 12.5mm thick gypsum board both sides and inclusive of 50mm thk Rockwool wool insulation of approved make (40kg/m3 density grade as specified) fixed to floor & RCC roof with screw, including provisions for grooves and fiber tape to be used for jointing and space/ cut-outs for electrical sockets/switches and conduits etc., as per detail drawings and specification and duly fixed to floor/wall/RCC roof with fasteners. Member placement to be worked out as per grooves.12mm comm. ply frame for all openings (doors/windows) and 10x10mm wide Aluminium Corner guard (as per approved make) edge protection profile at all the corners of the walls ,shall be provided. One side of the partition to be measured and paid for. Rockwool insulation shall be wrapped in Tissue paper prior to installation. Care must be taken that the boards are raised 3mm from the floor and in this gap, chauking compound is injected, for successive layers and similarly for the true ceiling channel. Gypsum partition to be installed as per OEM Installation Guidelines Make: USG Boral / Gyproc / India Gypsum Asouctic ratings to be maintained at, for Enclosed rooms: STC45 VP and Director’s room: STC50 VC & Meeting rooms: STC50
A42: a | B42: Above Door/Glass Partition | F42: SQM | G42: 35 | H42: 3170 | I42: =H42*G42 -> 110950
B43: Specs same as 2.01
A45: b | B45: 200mm thick partition for AV Support | C45: BOARD ROOM/AV AREA | F45: SQM | G45: 40 | H45: 5053 | I45: =H45*G45 -> 202120
B46: Specs same as 2.01, but with Aluminium channel and one side 12 mm ply finish
A48: 2.2 | B48: Ply backing
B49: Providing and fixing 8mm/12mm thick plywood backing on the existing surface Specification to be considered as per low VOC for LEED Compliance as per consultant guidelines. Decorative Cladding Acoustic Panelling Laminate Panelling Lacquered Glass Panelling | C49: MEETING RM, BOARD RM, MD CABIN, HOD CABIN, DESIGN FEATURE WALL, PRODUCT DISPLAY & CAFE | F49: SQM | G49: 350 | H49: 1378 | I49: =H49*G49 -> 482300
A51: 2.3 | B51: Decorative Wooden Rafter partition - pine wood
B52: Providing and fixing floor-to-ceiling decorative vertical wooden rafter partition comprising solid pine wood members of size 50 mm x 50 mm (or as per approved drawings), installed at uniform spacing to create a semi-open screening element. The rafters shall be fixed to a concealed MS support framework fabricated from minimum 25 x 25 x 1.6 mm thick box sections, securely anchored to the floor slab and ceiling structure. The MS framework shall be treated with anti-rust primer and finished with synthetic enamel paint. Pine wood members shall be machine-finished, sanded and coated with melamine/PU polish in approved shade and finish. The scope shall include all connectors, brackets, anchoring hardware, edge finishing, cutting, alignment, fixing and making good works, complete as per approved design, specifications and architect's drawings. | C52: RECEPTION, WORKSTATION AREA | E52: INR 555/SFT | F52: SQM | G52: 40 | H52: 6672 | I52: =H52*G52 -> 266880 | J52: Basic Rate: INR 300/SFT
A54: 2.4 | B54: Window Sill with Flexible Stone Finish | F54: RMT | G54: 165 | H54: 2067 | I54: =H54*G54 -> 341055
B55: Providing and fixing window sill finished with 2–3 mm thick natural flexible stone veneer sheets over 18 mm thick MDF/plywood backing substrate, in approved texture and shade, including adhesive fixing, edge finishing, joint treatment, cutting, alignment and all necessary accessories, complete as per detailed drawings and approved design. Size: 250 mm to 300 mm wide window sill, complete in all respects.
B57: TOTAL FOR PARTITION & ASSOCIATED WORKS | I57: =SUM(I38:I56) -> 2338455
A59: 3 | B59: CEILING WORKS
...

Sheet Modular Glass Partition & Doors
A1: SL NO | B1: ITEM DESCRIPTION | C1: LOCATION | D1: BASIC RATE | E1: UNIT | F1: QTY | G1: RATE (INR) | H1: AMOUNT (INR) | I1: REMARKS
A3: 1 | B3: MODULAR GLASS PARTITION
A5: 1.1 | B5: Glass Partition - (till 2400 mm high as per design)
B6: Providing & Fixing of Single glazed partitions: Use 10-12mm thick, clear, tempered glass with polished edges at both sides. 100mm wide Frame with a high-quality, slim-profile aluminum section of a specified make. Use stainless steel (SS) patch fittings and soft-close hinges. Aluminium section of 45*25mm. All sections duly coated in up to 15-20 microns and required accessories ie glass to glass aluminium I sections, T section & 90 degree sections & Glass packing to adjust the floor level. Ceiling profile, Floor profile and wall profile are 25 mm visible face and 45 mm wide & insertion of gasket to adhere the glass firm & airtight.- Black Powder Coated. Mode of measurements:- Front Elevation, one side only Glass: Saint-Gobain, ModiGuard.
A7: a | B7: Single Glazed Partition | E7: SQM | F7: 16 | G7: 5319 | H7: =G7*F7 -> 85104
A8: B | B8: Curve Single Glazed Partition | E8: SQM | F8: 65 | G8: 10154 | H8: =G8*F8 -> 660010
A10: 1.2 | B10: Above Glass Gypsum partition | E10: SQM | F10: 81 | G10: 3481 | H10: =G10*F10 -> 281961
B11: "Above glass partition (100mm thick Gypsum Partition) with Al Frame (both side gyp board) :- Providing and constructing 100 mm thick gypsum board partition below full-height glass using powder-coated aluminium framework with double skin gypsum board on both sides. Aluminium sections (minimum 1.2 mm thick) shall form the base and vertical framework at required spacing, securely anchored to the floor and ceiling. Both sides of the framework to be clad with 12.5 mm thick gypsum boards, screw-fixed and finished with joint tape and jointing compound in multiple coats. Partition height to be as per approved drawings, terminating at the glass sill level with proper interface detailing between gypsum and glass. Includes cut-outs for electrical boxes, MEP provisions, and necessary supports. All work to be completed in line, level, and plumb, finished smooth and ready for paint, as per architect instructions and approved details."
B13: TOTAL FOR MODULAR GLASS PARTITION | H13: =SUM(H3:H12) -> 1027075
A15: 2 | B15: DOORS
A17: 2.1 | B17: Fire Metal Doors
B18: Fire rated door of 45mm thick powdered coated metal shutter (single/double) . Door shall be of 2 hour fire resistance rating conforming to BS:476 part-22, IS:3614 suitable for mounting on MS frame as recommended by manufacturer, with heat activated intumescent fire seal strips of size 12x4mm fixed on all sides. Shutter to be mounted with approved make SS fire rated hinges with necessary screws and one coat of anti-termite fire resistant primer. Door shall be factory finished with powder coating. Rate to include, drop down seal and 3mm undercut, nail groove, complete hardware of approved make & provision for Access Control.
A19: a | B19: 1000mm X 2400mm - Single leaf door (FRD) with vision panel | C19: HUB ROOM | E19: NOS | F19: 1 | G19: 41073 | H19: =G19*F19 -> 41073
A21: 2.2 | B21: Solid Door
B22: Providing, making & fixing of 38mm thick single leaf Laminated Flush door fixed on frame with 4nos hinges & fixing lugs including 4 hinges per leaf per door, door closer/door stop on door completed as per design. The door shall have 500x225mm powder coated louvers to match door frame. Rate is inclusive of all necessary hardware (i.e. lock, handle on both sides, hinges, latch or tower bolt, door stopper, PVC buffer etc.), fixtures, laminate finish etc. Makes: Plywood/MDF: Greenply, CenturyPly, Action Tesa. Hardware: Hafele, Hettich, Ebco. Adhesives: Fevicol, Jivanjor.
A23: a | B23: Door Size : 1000mm X 2400mm | C23: WASHROOM | E23: NOS | F23: 2 | G23: 33071 | H23: =G23*F23 -> 66142
A24: b | B24: Door Size : 1200mm X 2400mm - with Vision Panel | C24: HANDICAP WASHROOM | E24: NOS | F24: 1 | G24: 42355 | H24: =G24*F24 -> 42355
A25: c | B25: Door Size : 1200mm X 2400mm - with Vision Panel | C25: DISHWASH AREA | E25: NOS | F25: 1 | G25: 42355 | H25: =G25*F25 -> 42355
A26: d | B26: Door Size :750mm X 2400mm | C26: JANITOR | E26: NOS | F26: 1 | G26: 27076 | H26: =G26*F26 -> 27076
A28: 2.3 | B28: Glass Door Stiled
B29: Fabricating and fixing of 10mm thk toughned glazed stiled doors of mentioned imension with necessary Stiled fittings lock Hardware with 300mm high Handle door stopper etc. 19mm thk MDF Door Jamb to be provided alound the Door & To be fixed on existing partiton / necessary wooden supports are inclusive. Design to be as per reference image Glass: Saint Gobain / Equivalent Hardware: Dorset / Ozone
A30: a | B30: Door Type - D1 1500mm x 2400mm Double Leaf Single Glazed Door. | C30: CAFETERIA | E30: NOS | F30: 1 | G30: 90511 | H30: =G30*F30 -> 90511
A31: b | B31: Door Type - D2 1000mm x 2400mm Single Leaf Single Glazed Door. | C31: all areas | E31: NOS | F31: 11 | G31: 48350 | H31: =G31*F31 -> 531850
A32: c | B32: Door Type - D3 1800mm x 2400mm Single Leaf Single Glazed Double Door | C32: WAITING FOYER | E32: NOS | F32: 1 | G32: 95733 | H32: =G32*F32 -> 95733
A33: d | B33: Door Type - D4 1800mm x 2400mm Single Leaf Single Glazed Double Door( F.R.D) | C33: MAIN ENTRANCE | E33: NOS | F33: 1 | G33: 110238 | H33: =G33*F33 -> 110238
B35: TOTAL FOR DOORS | H35: =SUM(H15:H34) -> 1047333
B37: TOTAL FOR MODULAR GLASS PARTITION & DOORS | H37: =H35+H13 -> 2074408

Sheet Signages
A1: SL NO | B1: ITEM DESCRIPTION | C1: LOCATION | D1: BASIC RATE | E1: UNIT | F1: QTY | G1: RATE (INR) | H1: AMOUNT (INR) | I1: REMARKS
A3: 1 | B3: Signages
A5: 1.1 | B5: Room Signages - 300mm x 100mm | C5: All Doors | E5: NOS | F5: 20 | G5: 870 | H5: =IF(F5="QRO",0,(F5*$G5)) -> 17400
B6: Supply and fixing of door signage of size 300mm x 100mm formed of anodised aluminium plate fixed with 3M double sided tape. To have black vinyl letters pasted onto the aluminium plate. Rate to include braille as per design
A8: 1.2 | B8: Push/Pull Signages - 100mm x 25mm | C8: All Doors | E8: SET | F8: 45 | G8: 653 | H8: =IF(F8="QRO",0,(F8*$G8)) -> 29385
B9: Supply and fixing of push / pull signage of size 4"x1" formed of SS plate with vinyl stickers in it fixed onto the door with 3M double sided tape. Rate to include braille as per design
A11: 1.3 | B11: Way Finding Signage - 10" x 7" | D11: INR 3600/UNIT | E11: NOS | F11: 30 | G11: 3916 | H11: =IF(F11="QRO",0,(F11*$G11)) -> 117480 | I11: Basic Rate: INR 1500/UNIT
B12: Way Finding Signage: 12mm thick Opaque White Acrylic laser cut to the size of the Sign, Bevell the edges to Smooth Finish, sides painted to Oracle Red Color Matte Finish / Oracle Grey Color Matte Finish. Artwork to be UV printed on Acrylic as per the Brand Guidelines. Sign to be installed Perpendicular to the Wall or Hung from ceiling with necessary fixtures. - Small Sign. Rate to include braille as per design
A14: 1.4 | B14: Corporate / GST Signage (450mm x600mm) | C14: Entrance | E14: NOS | F14: 1 | G14: 7833 | H14: =IF(F14="QRO",0,(F14*$G14)) -> 7833
B15: Supply & installation of corporate / GST signage in approved material & finish, size 450x600mm, fixed securely as per site requirements.
A17: 1.5 | B17: Brand Logo Display | C17: Reception, Behind Feature Wall, Cafeteria | D17: INR 50000/UNIT | E17: NOS | F17: 3 | G17: 52218 | H17: =IF(F17="QRO",0,(F17*$G17)) -> 156654 | I17: Basic Rate: INR 20000/Unit
B18: Supply, fabrication, and installation of brand logo in approved metal material with specified finish, fixed securely on the wall/backdrop using concealed mechanical fixing or approved adhesive method as per site requirement. The scope includes surface preparation, precision cutting, edge finishing, alignment, levelling, installation, and optional LED backlighting/illumination as per approved design, complete with all necessary hardware, accessories, wiring provisions, labour, tools, and tackles. Size: 1800 mm (W) × 600 mm (H)
A20: 1.6 | B20: Acrylic Design Letter- Design Feature wall | C20: Reception | D20: INR 90000/UNIT | E20: LS | F20: 1 | G20: 104440 | H20: =IF(F20="QRO",0,(F20*$G20)) -> 104440 | I20: Basic Rate: INR 50000/UNIT
B21: Providing, fabricating and fixing custom-made acrylic design lettering for feature wall graphics, comprising 10–15 mm thick laser-cut acrylic letters and graphical elements in approved font, size and finish. The scope shall include spacers/standoffs, adhesive fixing, templates for alignment, edge polishing, installation hardware and all accessories required for complete installation as per approved artwork, design and drawings. Complete in all respects.
B24: TOTAL FOR SIGNAGES | H24: =SUM(H3:H23) -> 433192

Sheet Graphics and Films
A1: SL NO | B1: ITEM DESCRIPTION | C1: LOCATION | D1: BASIC RATE | E1: UNIT | F1: QTY | G1: RATE (INR) | H1: AMOUNT (INR) | I1: REMARKS
A3: 1 | B3: Graphics and Films
A5: 1.1 | B5: Graphics / Branding – Wall & Partition | C5: CAFETERIA | D5: INR 125/SFT | E5: SQM | F5: 70 | G5: 1547 | H5: =IF(F5="QRO",0,(F5*$G5)) -> 108290 | I5: Basic Rate: INR 80/SFT
B6: Supply and installation of vinyl-based wall graphics as per the approved design. Materials shall be of premium quality, UV-resistant, and sourced from approved makes. Installation shall be executed neatly, ensuring proper alignment and a smooth, bubble-free finish as per the approved mock-up.
A8: 1.2 | B8: Framed Graphics / Framed Artwork
B9: Supply and installation of high-quality canvas artwork mounted in wooden or MDF frames as per the approved design. Frames shall be finished as per the approved make and installed securely, level, and neatly aligned, matching the approved mock-up.
A10: a | B10: Size: 600mm X 450mm | C10: ALL AREAS | D10: INR 2400/UNIT | E10: NOS | F10: 10 | G10: 2901 | H10: =IF(F10="QRO",0,(F10*$G10)) -> 29010 | I10: Basic Rate: INR 1200/UNIT
A11: b | B11: Size: 1500mm X 900mm | C11: ALL AREAS | D11: INR 3600/UNIT | E11: NOS | F11: 5 | G11: 4341 | H11: =IF(F11="QRO",0,(F11*$G11)) -> 21705 | I11: Basic Rate: INR 1800/UNIT
A13: 1.3 | B13: Primer for Wallpaper / Graphics | C13: ALL AREAS | E13: SQM | F13: 140 | G13: 155 | H13: =IF(F13="QRO",0,(F13*$G13)) -> 21700
B14: Providing and applying Oil based primer finish to walls of approved shade, texture. Existing wall surfaces to be prepare by scraping away any loose particles, dust, etc by washing and scrubbing and 2 coats of oil based primer applied. The wall surfaces are then smoothened using chalk putty as directed. Surfaces are then sandpapered to achieve a smooth finish and made ready to receive wallpaper / graphics as directed.Note : Rate should be inclusive of Masking for fixtures & wooden frames.
A16: 1.4 | B16: Frost Film | C16: MEETING ROOM, HOD CABINS, MD CABIN | D16: INR 110/SFT | E16: SQM | F16: 110 | G16: 1209 | H16: =IF(F16="QRO",0,(F16*$G16)) -> 132990 | I16: Basic Rate: INR 60/SFT
B17: Supply & fixing of approved coloured Frost film/ Privacy Film for Glass Partitions as per manufacturer specification and as per architect instruction.(The successful vendor should submit 10 years Warranty certificate to the client. Product to be certified by Manufacturer's Representative). Wastages to be included in the quoted rate.
B19: TOTAL FOR GRAPHICS & FROST FILM | H19: =SUM(H3:H18) -> 313695

Sheet Blinds
A1: SL NO | B1: ITEM DESCRIPTION | C1: LOCATION | D1: BASIC RATE | E1: UNIT | F1: QTY | G1: RATE (INR) | H1: AMOUNT (INR) | I1: REMARKS
A3: 1 | B3: Blinds
B5: Supply and installation of Roller blinds: Use high-quality, motorized roller blinds with flame-retardant, acoustic fabric. List of makes: roller blinds including gear based mechanism as per specifications mentioned below. Fabric to be combination of glass fiber and polyester as per manufacturer's standards.Bottom of the blind shall be provided with steel profile . The fabric shall be enclosed in the suitably created pocket along with the tube. The tube shall be closed from sides with end caps to give a neat look.Clutch driven roller mechanism with stopper and load bar, all in SS finish to be considered. Make: Vista / Hunter Douglas / MAC
A6: 1.1 | B6: Supply & Installation of manually operated roller blinds as per approved style and shade | C6: ALONG FACADE SIDE | D6: INR 115/SFT | E6: SQM | F6: 450 | G6: 1305 | H6: =IF(F6="QRO",0,(F6*$G6)) -> 587250 | I6: Basic Rate: INR 75/SFT
B7: "Supply & Installation of manually operated Roller blinds as per approved style and shade. HARDWARE - Top Tube : Made of extruded aluminium 38 mm Dia. With wall thickness of 1.2 mm with spline adoptable to accommodate clutch of ACMEDA make. Clutch Mechanism : Moulded plastic having antifriction additive with Glass fibre reinforcement. Should have a minimum lifting capacity of 8 lbs. Operating Chain: #10 steel ball chain adoptable to the clutch pitch for smooth lifting & lowering of blind. Locking Member : #12 steel stop locks for limit setting adoptable to the steel chain. Load Tube : 38 mm Extruded aluminium wall thickness :1.2 mm + / - 5%. Bonding ( Fabric > Tube ) : 15 mm wide double sided adhesive tape of 3M. SPRING BOOSTERS: All blinds above 2.4 mtr width or 3.36 mtr height and for total weight exceeding 4.0 kgs. Bottom Bar : aluminium extruded box section with powder coatecd finish matching the roller fabric -Min weight to be 365 gms / Lmr for a perfect fall of fabric to avoid warpage / floating.Instalattion to be insert type with end caps. Screens to be with 3% Openness. Fabric selection will be based on the approval of mock up (Vendor to do the mock up at site)"
A8: 1.2 | B8: Supply & Installation of motorised roller blinds as per approved style and shade | C8: BOARD ROOM, MD CABIN | D8: INR 485/SFT | E8: SQM | F8: 55 | G8: 5805.69 | H8: =IF(F8="QRO",0,(F8*$G8)) -> 319312.95 | I8: Basic Rate: INR 350/SFT
B9: Motorized Blinds blackout blind fabric as per site measurements spanning between mullions Operation: Tubular motorized system, smooth and silent operation Motor: Tubular motor with built-in limit switches, compatible with wall switch / remote control (BMS integration, if required, shall be paid separately) Control: Individual / group control via wall-mounted switch or remote, as specified Roller Tube: Extruded aluminium roller with adequate diameter as per blind width Supply & Installation of Silent Motors with 1 motor driving 2 blinds Maximum size 2.2 meter width and 3.36 meter height along with remote control Motor Specification : Silent motor 3/30 RTS For approved size of Blinds as per project specific requirements with Open/Close/Stop operation of Blinds from Remote or wireless Remote Or third party system , will fix on wooden palmate/ceiling/walls. Silent Blinds motor having voltage range of 230V – Frequency 50Hz, ,Radio Frequency 433.42M,Range 20 m with 2 reinforced concrete walls to be passed through, Nominal Torque (nm) 3 nm,RPM 30 rpm, Sound level (dBA) 42dBA, Maximum Current 0.9 A ,Adjustable Limits, Blind Maximum Weight capacity 10kg, 20kg ,it will cover upto 3 meter straight window, diameter of the motor should be 40 mm, Thermal Time 4 minutes Supply AC Index Protection Rating IP30 Limit Switch Unit Electronic Temperature Working Range 0ºC to +60ºC Electric Insulation Class. Having ultra powerfull,ultra flexible, ultra quiet. Control from Remote or Wireless wall mounted switch using frequency also Compatible with multiple technologies (WT/DCT/RTS/RS485) to meet the needs of smart buildings as recommended by the manufacturer for suitable above motor & warranty of the motors should be 5 years. 1 motor driving 1 blind Maximum size 2.5 meter width and 3.6 meter height.
B10: TOTAL FOR BLINDS | H10: =SUM(H3:H9) -> 906562.95

Sheet Planters
A1: SL NO | B1: ITEM DESCRIPTION | C1: BASIC RATE | D1: UNIT | E1: QTY | F1: RATE (INR) | G1: AMOUNT (INR) | H1: IMAGES | I1: REMARKS
A3: 1 | B3: Planters
B5: SPECIFICATIONS : Planters shall be made of high-quality Fibre Reinforced Plastic (FRP), molded to the required shape and size. The material shall be UV-resistant, durable, and corrosion-free, making it suitable for indoor and semi-outdoor use. The wall thickness shall be 4–5 mm to ensure rigidity and strength, and all surfaces must be smooth, even, and free from joints or defects. The exterior shall have a gel-coated finish in a matte or semi-gloss look, in the approved color, while the interior shall be coated with waterproof resin to prevent leakage or moisture damage. Planters shall be fabricated according to the approved design and dimensions, whether square, rectangular, cylindrical, or custom shapes, and each planter shall include a drainage hole with a plug or mesh. Planters shall be supplied empty unless otherwise specified, ready for planting. GI trays shall be provided beneath the planters to protect carpentry, flooring, or storage items. The rate shall include material, fabrication, finishing, delivery, placement, and the protective tray, complete in all respects.
A7: 1.1 | B7: FRP planter 1 Size: 300-450 dia x 900mm High. species : Schefflera arboricola Xanadu - Medium Dwarf Umbrella Tree. | C7: INR 2500/Unit | D7: NOS | E7: 30 | F7: 2924 | G7: =F7*E7 -> 87720 | I7: Half The Basic Rate: INR 1250/UNIT
A9: 1.2 | B9: FRP planter 2 Planter Size: 450 dia x 900-1050mm High. Plant Species : Schefflera arboricola Dwarf Umbrella Tree. | C9: INR 3500/Unit | D9: NOS | E9: 15 | F9: 4177 | G9: =F9*E9 -> 62655 | I9: Basic Rate: INR 1750/UNIT
A11: 1.3 | B11: Planter Material : Wonido Plant Pot Removable Plant Insert for Indoor and Outdoor Use Made of High-Quality Polypropylene. Size : Height 85 mm Diameter 38 mm Plant White Tulips (Cut Flowers) | C11: INR 4500/Unit | D11: NOS | E11: 15 | F11: 5222 | G11: =F11*E11 -> 78330 | I11: Basic Rate: INR 2250/UNIT
A13: 1.4 | B13: Planter Material : Wonido Plant Pot Removable Plant Insert for Indoor and Outdoor Use Made of High-Quality Polypropylene. Size : Height 55 cm Diameter 50 cm Matt White with Removable Plant Insert for Indoor and Outdoor Use Made of High-Quality Polypropylene. Plant: Lady Palm — Rhapis excelsa. Areca Palm (Dypsis lutescens) Ficus benjamina | C13: INR 4500/Unit | D13: NOS | E13: 15 | F13: 5222 | G13: =F13*E13 -> 78330 | I13: Basic Rate: INR 2250/UNIT
A15: 1.5 | B15: Planter Material : Wonido Plant Pot Removable Plant Insert for Indoor and Outdoor Use Made of High-Quality Polypropylene. Size : Height 75 cm Diameter 42 cm Matt White with Removable Plant Insert for Indoor and Outdoor Use Made of High-Quality Polypropylene. Plant: Dieffenbachia Green Magic Dieffenbachia Green Magic Philodendron Sellom (Medium) Heart Leaf Money Plant | C15: INR 3500/Unit | D15: NOS | E15: 12 | F15: 4178 | G15: =F15*E15 -> 50136 | I15: Basic Rate: INR 1750/UNIT
A17: 1.6 | B17: Planter Material : Wonido Plant Removable Plant Insert for Indoor and Outdoor Use Made of High-Quality Polypropylene. Size : Height 100MM Diameter 150MM HIGH Matt White with Removable Plant Insert for Indoor and Outdoor Use Made of High-Quality Polypropylene. Plant: Dieffenbachia Green Magic Teardrop Peperomia Varigated Turtle Vine (Callisia Repens) MONEY PLANT Marble Queen Philodendron Sellom | C17: INR 5000/Unit | D17: NOS | E17: 12 | F17: 5744 | G17: =F17*E17 -> 68928 | I17: Basic Rate: INR 2500/UNIT
B19: TOTAL FOR PLANTERS | G19: =SUM(G3:G18) -> 426099

Sheet Modular Furniture
A1: SL NO | B1: ITEM DESCRIPTION | C1: IMAGES | D1: BASIC RATE | E1: UNIT | F1: QTY | G1: RATE (INR) | H1: AMOUNT (INR) | I1: Remarks
A3: 1 | B3: Modular Furniture
A5: 1.01 | B5: Workstation Linear Sharing/Non sharing - 1500mm X 750mm | E5: NOS | F5: 38 | G5: 12619 | H5: =G5*F5 -> 479522
